<?xml version="1.0" ?>
<!-- =================================================================================== -->
<!-- |    This document was autogenerated by xacro from smartcar.xacro                 | -->
<!-- |    EDITING THIS FILE BY HAND IS NOT RECOMMENDED                                 | -->
<!-- =================================================================================== -->
<robot name="smartcar" xmlns:body="http://playerstage.sourceforge.net/gazebo/xmlschema/#body" xmlns:controller="http://playerstage.sourceforge.net/gazebo/xmlschema/#controller" xmlns:gazebo="http://playerstage.sourceforge.net/gazebo/xmlschema/#gz" xmlns:geom="http://playerstage.sourceforge.net/gazebo/xmlschema/#geom" xmlns:interface="http://playerstage.sourceforge.net/gazebo/xmlschema/#interface" xmlns:joint="http://playerstage.sourceforge.net/gazebo/xmlschema/#joint" xmlns:model="http://playerstage.sourceforge.net/gazebo/xmlschema/#model" xmlns:physics="http://playerstage.sourceforge.net/gazebo/xmlschema/#physics" xmlns:renderable="http://playerstage.sourceforge.net/gazebo/xmlschema/#renderable" xmlns:rendering="http://playerstage.sourceforge.net/gazebo/xmlschema/#rendering" xmlns:sensor="http://playerstage.sourceforge.net/gazebo/xmlschema/#sensor" xmlns:xi="http://www.w3.org/2001/XInclude">
  <!-- Macro for SmartCar body. Including Gazebo extensions, but does not include Kinect -->
  <include filename="/home/wangdong/willand_robot/src/four_wheel_drive/robot_model/xacro/smartcar_sim.xacro"/>
  <link name="base_footprint">
    <visual>
      <origin rpy="0 0 0" xyz="0 0 0"/>
      <geometry>
        <box size="0.001 0.001 0.001"/>
      </geometry>
    </visual>
  </link>
  <joint name="base_footprint_joint" type="fixed">
    <origin rpy="0 0 0" xyz="0 0 0"/>
    <parent link="base_footprint"/>
    <child link="base_link"/>
  </joint>
  <link name="base_link">
    <inertial>
      <mass value="10.0"/>
      <inertia ixx="0.021666666666666667" ixy="0" ixz="0" iyy="0.05241666666666667" iyz="0" izz="0.07341666666666667"/>
    </inertial>
    <visual>
      <origin rpy="0 0 0" xyz="0 0 0.055"/>
      <geometry>
        <box size="0.25 0.16 0.02"/>
      </geometry>
      <material name="blue">
        <color rgba="0 0 0.8 1"/>
      </material>
    </visual>
    <collision>
      <origin rpy="0 0 0" xyz="0 0 0.055"/>
      <geometry>
        <box size="0.25 0.16 0.02"/>
      </geometry>
    </collision>
  </link>
  <link name="left_front_wheel">
    <inertial>
      <mass value="5"/>
      <inertia ixx="0.0009479166666666669" ixy="0" ixz="0" iyy="0.0009479166666666669" iyz="0" izz="0.0015625"/>
    </inertial>
    <visual>
      <origin rpy="0 0 0" xyz="0 0 0"/>
      <geometry>
        <cylinder length=".02" radius="0.025"/>
      </geometry>
      <material name="black">
        <color rgba="0 0 0 1"/>
      </material>
    </visual>
    <collision>
      <origin rpy="0 0 0" xyz="0 0 0"/>
      <geometry>
        <cylinder length=".02" radius="0.025"/>
      </geometry>
    </collision>
  </link>
  <!--
	<joint name="left_front_wheel_joint" type="continuous">
		<axis xyz="0 0 1"/>
		<parent link="base_link"/>
		<child link="left_front_wheel"/>
		<origin rpy="${M_PI/2} 0 0" xyz="0.08 0.08 0.025"/>
		<limit effort="100" velocity="100"/>
		<joint_properties damping="0.0" friction="0.0"/>
	</joint>
-->
  <link name="right_front_wheel">
    <inertial>
      <mass value="5"/>
      <inertia ixx="0.0009479166666666669" ixy="0" ixz="0" iyy="0.0009479166666666669" iyz="0" izz="0.0015625"/>
    </inertial>
    <visual>
      <origin rpy="0 0 0" xyz="0 0 0"/>
      <geometry>
        <cylinder length=".02" radius="0.025"/>
      </geometry>
      <material name="black">
        <color rgba="0 0 0 1"/>
      </material>
    </visual>
    <collision>
      <origin rpy="0 0 0" xyz="0 0 0"/>
      <geometry>
        <cylinder length=".02" radius="0.025"/>
      </geometry>
    </collision>
  </link>
  <!--
	<joint name="right_front_wheel_joint" type="continuous">
		<axis xyz="0 0 1"/>
		<parent link="base_link"/>
		<child link="right_front_wheel"/>
		<origin rpy="${M_PI/2} 0 0" xyz="0.08 -0.08 0.025"/>
		<limit effort="100" velocity="100"/>
		<joint_properties damping="0.0" friction="0.0"/>
 	</joint>
-->
  <link name="left_back_wheel">
    <inertial>
      <mass value="5"/>
      <inertia ixx="0.0009479166666666669" ixy="0" ixz="0" iyy="0.0009479166666666669" iyz="0" izz="0.0015625"/>
    </inertial>
    <visual>
      <origin rpy="0 0 0" xyz="0 0 0"/>
      <geometry>
        <cylinder length=".02" radius="0.025"/>
      </geometry>
      <material name="black">
        <color rgba="0 0 0 1"/>
      </material>
    </visual>
    <collision>
      <origin rpy="0 0 0" xyz="0 0 0"/>
      <geometry>
        <cylinder length=".02" radius="0.025"/>
      </geometry>
    </collision>
  </link>
  <joint name="left_back_wheel_joint" type="continuous">
    <axis xyz="0 0 1"/>
    <parent link="base_link"/>
    <child link="left_back_wheel"/>
    <origin rpy="0 1.57079632679 1.57079632679" xyz="-0.08 0.08 0.025"/>
    <dynamics damping="0.0"/>
    <limit effort="100" velocity="100"/>
    <joint_properties damping="0.0" friction="0.0"/>
  </joint>
  <link name="right_back_wheel">
    <inertial>
      <mass value="5.0"/>
      <inertia ixx="0.0009479166666666669" ixy="0" ixz="0" iyy="0.0009479166666666669" iyz="0" izz="0.0015625"/>
    </inertial>
    <visual>
      <origin rpy="0 0 0" xyz="0 0 0"/>
      <geometry>
        <cylinder length=".02" radius="0.025"/>
      </geometry>
      <material name="black">
        <color rgba="0 0 0 1"/>
      </material>
    </visual>
    <collision>
      <origin rpy="0 0 0" xyz="0 0 0"/>
      <geometry>
        <cylinder length=".02" radius="0.025"/>
      </geometry>
    </collision>
  </link>
  <joint name="right_back_wheel_joint" type="continuous">
    <axis xyz="0 0 1"/>
    <parent link="base_link"/>
    <child link="right_back_wheel"/>
    <origin rpy="0 1.57079632679 1.57079632679" xyz="-0.08 -0.08 0.025"/>
    <dynamics damping="0.0"/>
    <limit effort="100" velocity="100"/>
    <joint_properties damping="0.0" friction="0.0"/>
  </joint>
  <link name="left_bridge">
    <inertial>
      <origin rpy="0 0 0" xyz="0 0 0"/>
      <mass value="0.3"/>
      <inertia ixx="3e-06" ixy="0" ixz="0" iyy="3e-06" iyz="0" izz="3e-06"/>
    </inertial>
    <visual>
      <origin rpy="0 0 0" xyz="0 0 0"/>
      <geometry>
        <sphere radius="0.005"/>
      </geometry>
      <material name="red">
        <color rgba="1 0 0 1"/>
      </material>
    </visual>
    <collision>
      <origin rpy="0 0 0" xyz="0 0 0"/>
      <geometry>
        <sphere radius="0.005"/>
      </geometry>
    </collision>
  </link>
  <joint name="left_bridge_to_bridge" type="revolute">
    <parent link="base_link"/>
    <child link="left_bridge"/>
    <origin rpy="0 0 1.57079632679" xyz="0.08 -0.07 0.025"/>
    <axis xyz="0 0 -1"/>
    <dynamics damping="0.0"/>
    <limit effort="2.5" lower="-0.785" upper="0.785" velocity="10"/>
    <joint_properties damping="20.0" friction="20.0"/>
  </joint>
  <link name="right_bridge">
    <inertial>
      <origin rpy="0 0 0" xyz="0 0 0"/>
      <mass value="0.3"/>
      <inertia ixx="3e-06" ixy="0" ixz="0" iyy="3e-06" iyz="0" izz="3e-06"/>
    </inertial>
    <visual>
      <origin rpy="0 0 0" xyz="0 0 0"/>
      <geometry>
        <sphere radius="0.005"/>
      </geometry>
      <material name="red">
        <color rgba="1 0 0 1"/>
      </material>
    </visual>
    <collision>
      <origin rpy="0 0 0" xyz="0 0 0"/>
      <geometry>
        <sphere radius="0.005"/>
      </geometry>
    </collision>
  </link>
  <joint name="right_bridge_to_bridge" type="revolute">
    <parent link="base_link"/>
    <child link="right_bridge"/>
    <origin rpy="0 0 1.57079632679" xyz="0.08 0.07 0.025"/>
    <axis xyz="0 0 -1"/>
    <dynamics damping="0.0"/>
    <limit effort="2.5" lower="-0.785" upper="0.785" velocity="10"/>
    <joint_properties damping="20.0" friction="20.0"/>
  </joint>
  <joint name="right_front_wheel_to_bridge" type="continuous">
    <axis xyz="0 0 1"/>
    <parent link="right_bridge"/>
    <child link="right_front_wheel"/>
    <origin rpy="0 1.57079632679 0" xyz="0.01 0 0"/>
    <dynamics damping="0.0"/>
    <limit effort="100" velocity="100"/>
    <joint_properties damping="0.0" friction="0.0"/>
  </joint>
  <joint name="left_front_wheel_to_bridge" type="continuous">
    <axis xyz="0 0 1"/>
    <parent link="left_bridge"/>
    <child link="left_front_wheel"/>
    <origin rpy="0 1.57079632679 0" xyz="-0.01 0 0"/>
    <dynamics damping="0.0"/>
    <limit effort="100" velocity="100"/>
    <joint_properties damping="0.0" friction="0.0"/>
  </joint>
  <link name="camera_link">
    <inertial>
      <origin rpy="0 0 0" xyz="0 0 0"/>
      <mass value="0.1"/>
      <inertia ixx="1.5e-05" ixy="0.0" ixz="0.0" iyy="7.708333333333334e-06" iyz="0.0" izz="7.708333333333334e-06"/>
    </inertial>
    <visual>
      <origin rpy="0 0 0" xyz="0 0 0"/>
      <geometry>
        <box size=".005 .03 .03"/>
      </geometry>
      <material name="white">
        <color rgba="1 1 1 1"/>
      </material>
    </visual>
    <collision>
      <origin rpy="0 0 0" xyz="0 0 0"/>
      <geometry>
        <box size=".005 .03 .03"/>
      </geometry>
    </collision>
  </link>
  <joint name="tobox" type="fixed">
    <parent link="base_link"/>
    <child link="camera_link"/>
    <origin rpy="0 0 0" xyz="0.115 0 0.08"/>
  </joint>
  <joint name="carriage_front_joint" type="fixed">
    <origin rpy="0 0 0" xyz="0.04 0 0.075"/>
    <parent link="base_link"/>
    <child link="carriage_front"/>
  </joint>
  <link name="carriage_front">
    <visual>
      <origin rpy="0 0 0" xyz="0 0 0"/>
      <geometry>
        <cylinder length="0.025" radius="0.004"/>
      </geometry>
      <material name="black">
        <color rgba="0 0 0 1"/>
      </material>
    </visual>
    <collision>
      <origin rpy="0 0 0" xyz="0 0 0"/>
      <geometry>
        <cylinder length="0.025" radius="0.004"/>
      </geometry>
    </collision>
    <inertial>
      <mass value="0.02"/>
      <inertia ixx="1.1216666666666668e-06" ixy="0" ixz="0" iyy="1.1216666666666668e-06" iyz="0" izz="1.6e-07"/>
    </inertial>
  </link>
  <joint name="carriage_left_joint" type="fixed">
    <origin rpy="0 0 0" xyz="0 -0.04 0.075"/>
    <parent link="base_link"/>
    <child link="carriage_left"/>
  </joint>
  <link name="carriage_left">
    <visual>
      <origin rpy="0 0 0" xyz=" 0 0 0 "/>
      <geometry>
        <cylinder length="0.025" radius="0.004"/>
      </geometry>
      <material name="black">
        <color rgba="0 0 0 1"/>
      </material>
    </visual>
    <collision>
      <origin rpy="0 0 0" xyz="0 0 0"/>
      <geometry>
        <cylinder length="0.025" radius="0.004"/>
      </geometry>
    </collision>
    <inertial>
      <mass value="0.02"/>
      <inertia ixx="1.1216666666666668e-06" ixy="0" ixz="0" iyy="1.1216666666666668e-06" iyz="0" izz="1.6e-07"/>
    </inertial>
  </link>
  <joint name="carriage_right_joint" type="fixed">
    <origin rpy="0 0 0" xyz="0 0.04 0.075"/>
    <parent link="base_link"/>
    <child link="carriage_right"/>
  </joint>
  <link name="carriage_right">
    <visual>
      <origin rpy="0 0 0" xyz="0 0 0"/>
      <geometry>
        <cylinder length="0.025" radius="0.004"/>
      </geometry>
      <material name="black">
        <color rgba="0 0 0 1"/>
      </material>
    </visual>
    <collision>
      <origin rpy="0 0 0" xyz=" 0 0 0 "/>
      <geometry>
        <cylinder length="0.025" radius="0.004"/>
      </geometry>
    </collision>
    <inertial>
      <mass value="0.02"/>
      <inertia ixx="1.1216666666666668e-06" ixy="0" ixz="0" iyy="1.1216666666666668e-06" iyz="0" izz="1.6e-07"/>
    </inertial>
  </link>
  <joint name="carriage_back_joint" type="fixed">
    <origin rpy="0 0 0" xyz="-0.04 0 0.075"/>
    <parent link="base_link"/>
    <child link="carriage_back"/>
  </joint>
  <link name="carriage_back">
    <visual>
      <origin rpy="0 0 0" xyz="0 0 0"/>
      <geometry>
        <cylinder length="0.025" radius="0.004"/>
      </geometry>
      <material name="black">
        <color rgba="0 0 0 1"/>
      </material>
    </visual>
    <collision>
      <origin rpy="0 0 0" xyz="0 0 0"/>
      <geometry>
        <cylinder length="0.025" radius="0.004"/>
      </geometry>
    </collision>
    <inertial>
      <mass value="0.02"/>
      <inertia ixx="1.1216666666666668e-06" ixy="0" ixz="0" iyy="1.1216666666666668e-06" iyz="0" izz="1.6e-07"/>
    </inertial>
  </link>
  <link name="laser_link">
    <visual>
      <origin rpy="0 0 0" xyz="0 0 0"/>
      <geometry>
        <cylinder length="0.05" radius="0.05"/>
      </geometry>
      <material name="black">
        <color rgba="0 0 0 1"/>
      </material>
    </visual>
    <collision>
      <origin rpy="0 0 0" xyz="0 0 0"/>
      <geometry>
        <cylinder length="0.05" radius="0.05"/>
      </geometry>
    </collision>
    <inertial>
      <mass value="0.17"/>
      <inertia ixx="0.0001416666666666667" ixy="0" ixz="0" iyy="0.0001416666666666667" iyz="0" izz="0.00021250000000000002"/>
    </inertial>
  </link>
  <joint name="laser_joint" type="fixed">
    <origin rpy="0 0 0" xyz="0 0 0.11"/>
    <parent link="base_link"/>
    <child link="laser_link"/>
  </joint>
  <link name="Raspberry_Pi">
    <inertial>
      <origin rpy="0 0 0" xyz="0 0 0"/>
      <mass value="0.1"/>
      <inertia ixx="9.520833333333332e-05" ixy="0.0" ixz="0.0" iyy="2.8541666666666668e-05" iyz="0.0" izz="9.520833333333332e-05"/>
    </inertial>
    <visual>
      <origin rpy="0 0 0" xyz="0 0 0"/>
      <geometry>
        <box size=".055 .105 .02"/>
      </geometry>
      <material name="white">
        <color rgba="1 1 1 1"/>
      </material>
    </visual>
    <collision>
      <origin rpy="0 0 0" xyz="0 0 0"/>
      <geometry>
        <box size=".055 .105 .02"/>
      </geometry>
    </collision>
  </link>
  <joint name="Raspberry_Pi_joint" type="fixed">
    <parent link="base_link"/>
    <child link="Raspberry_Pi"/>
    <origin xyz="-0.09 0 0.075"/>
  </joint>
  <link name="imu_link">
    <inertial>
      <origin rpy="0 0 0" xyz="0 0 0"/>
      <mass value="0.04"/>
      <inertia ixx="1.3633333333333336e-06" ixy="0.0" ixz="0.0" iyy="5.100000000000001e-07" iyz="0.0" izz="1.8133333333333335e-06"/>
    </inertial>
    <visual>
      <geometry>
        <box size=".02 .012 .003"/>
      </geometry>
      <material name="yellow">
        <color rgba="0 0.5 0.5 1"/>
      </material>
    </visual>
    <collision>
      <origin rpy="0 0 0" xyz="0 0 0"/>
      <geometry>
        <box size=".02 .012 .003"/>
      </geometry>
    </collision>
  </link>
  <joint name="imu_joint" type="fixed">
    <parent link="Raspberry_Pi"/>
    <child link="imu_link"/>
    <origin xyz="0 0 0.01"/>
  </joint>
  <gazebo reference="base_footprint">
    <turnGravityOff>false</turnGravityOff>
  </gazebo>
  <gazebo reference="base_link">
    <material>Gazebo/Blue</material>
  </gazebo>
  <gazebo reference="left_front_wheel">
    <material>Gazebo/FlatBlack</material>
  </gazebo>
  <gazebo reference="right_front_wheel">
    <material>Gazebo/FlatBlack</material>
  </gazebo>
  <gazebo reference="left_back_wheel">
    <material>Gazebo/FlatBlack</material>
  </gazebo>
  <gazebo reference="right_back_wheel">
    <material>Gazebo/FlatBlack</material>
  </gazebo>
  <gazebo reference="left_bridge">
    <material>Gazebo/Red</material>
  </gazebo>
  <gazebo reference="right_bridge">
    <material>Gazebo/Red</material>
  </gazebo>
  <gazebo reference="camera_link">
    <material>Gazebo/White</material>
  </gazebo>
  <gazebo reference="carriage_front">
    <material>Gazebo/FlatBlack</material>
  </gazebo>
  <gazebo reference="carriage_left">
    <material>Gazebo/FlatBlack</material>
  </gazebo>
  <gazebo reference="carriage_right">
    <material>Gazebo/FlatBlack</material>
  </gazebo>
  <gazebo reference="carriage_back">
    <material>Gazebo/FlatBlack</material>
  </gazebo>
  <gazebo reference="laser_link">
    <material>Gazebo/FlatBlack</material>
  </gazebo>
  <gazebo reference="Raspberry_Pi">
    <material>Gazebo/White</material>
  </gazebo>
  <gazebo reference="imu_link">
    <material>Gazebo/Yellow</material>
  </gazebo>
  <!-- IMU sensor -->
  <gazebo reference="imu_link">
    <gravity>true</gravity>
    <sensor name="imu_sensor" type="imu">
      <always_on>true</always_on>
      <update_rate>100</update_rate>
      <visualize>true</visualize>
      <topic>__default_topic__</topic>
      <plugin filename="libgazebo_ros_imu_sensor.so" name="imu_plugin">
        <topicName>imu</topicName>
        <bodyName>imu_link</bodyName>
        <updateRateHZ>100.0</updateRateHZ>
        <gaussianNoise>0.0</gaussianNoise>
        <xyzOffset>0 0 0</xyzOffset>
        <rpyOffset>0 0 0</rpyOffset>
        <frameName>imu_link</frameName>
      </plugin>
      <pose>0 0 0 0 0 0</pose>
    </sensor>
  </gazebo>
  <!-- camera -->
  <gazebo reference="camera_link">
    <sensor name="camera1" type="camera">
      <update_rate>30.0</update_rate>
      <camera name="head">
        <horizontal_fov>1.3962634</horizontal_fov>
        <image>
          <width>800</width>
          <height>800</height>
          <format>R8G8B8</format>
        </image>
        <clip>
          <near>0.02</near>
          <far>300</far>
        </clip>
        <noise>
          <type>gaussian</type>
          <!-- Noise is sampled independently per pixel on each frame.
						That pixel's noise value is added to each of its color
						channels, which at that point lie in the range [0,1]. -->
          <mean>0.0</mean>
          <stddev>0.007</stddev>
        </noise>
      </camera>
      <plugin filename="libgazebo_ros_camera.so" name="camera_controller">
        <alwaysOn>true</alwaysOn>
        <updateRate>0.0</updateRate>
        <cameraName>camera</cameraName>
        <imageTopicName>image_raw</imageTopicName>
        <cameraInfoTopicName>camera_info</cameraInfoTopicName>
        <frameName>camera_link</frameName>
        <hackBaseline>0.07</hackBaseline>
        <distortionK1>0.0</distortionK1>
        <distortionK2>0.0</distortionK2>
        <distortionK3>0.0</distortionK3>
        <distortionT1>0.0</distortionT1>
        <distortionT2>0.0</distortionT2>
      </plugin>
    </sensor>
  </gazebo>
  <gazebo reference="laser_link">
    <sensor name="head_hokuyo_sensor" type="ray">
      <pose>0 0 0 0 0 0</pose>
      <visualize>false</visualize>
      <update_rate>40</update_rate>
      <ray>
        <scan>
          <horizontal>
            <samples>720</samples>
            <resolution>1</resolution>
            <min_angle>-1.570796</min_angle>
            <max_angle>1.570796</max_angle>
          </horizontal>
        </scan>
        <range>
          <min>0.10</min>
          <max>30.0</max>
          <resolution>0.01</resolution>
        </range>
        <noise>
          <type>gaussian</type>
          <!-- Noise parameters based on published spec for Hokuyo laser
						achieving "+-30mm" accuracy at range < 10m.  A mean of 0.0m and
						stddev of 0.01m will put 99.7% of samples within 0.03m of the true
						reading. -->
          <mean>0.0</mean>
          <stddev>0.01</stddev>
        </noise>
      </ray>
      <plugin filename="libgazebo_ros_laser.so" name="gazebo_ros_head_hokuyo_controller">
        <topicName>laser/scan</topicName>
        <frameName>laser_link</frameName>
      </plugin>
    </sensor>
  </gazebo>
  <!-- Drive controller -->
  <!--	<gazebo>
		<plugin name="skid_steer_drive_controller" filename="libgazebo_ros_skid_steer_drive.so">
			<updateRate>100.0</updateRate>
			<robotNamespace></robotNamespace>
			<leftFrontJoint>left_front_wheel_joint</leftFrontJoint>
			<rightFrontJoint>right_front_wheel_joint</rightFrontJoint>
			<leftRearJoint>left_back_wheel_joint</leftRearJoint>
			<rightRearJoint>right_back_wheel_joint</rightRearJoint>
			<wheelSeparation>0.16</wheelSeparation>
			<wheelDiameter>0.05</wheelDiameter>
			<commandTopic>cmd_vel</commandTopic>
			<odometryTopic>odom</odometryTopic>
			<robotBaseFrame>base_footprint</robotBaseFrame>
			<odometryFrame>odom</odometryFrame>
			<torque>15</torque>
			<topicName>cmd_vel</topicName>
			<broadcastTF>1</broadcastTF>
	  	</plugin>
	</gazebo>
-->
  <!--
	<gazebo>
            <plugin name="differential_drive_controller"
                    filename="libgazebo_ros_diff_drive.so">
                <rosDebugLevel>Debug</rosDebugLevel>
                <publishWheelTF>true</publishWheelTF>
                <robotNamespace>/</robotNamespace>
                <publishTf>1</publishTf>
                <publishWheelJointState>true</publishWheelJointState>
                <alwaysOn>true</alwaysOn>
                <updateRate>100.0</updateRate>
                <legacyMode>true</legacyMode>
                <leftJoint>left_back_wheel_joint</leftJoint>
                <rightJoint>right_back_wheel_joint</rightJoint>
                <wheelSeparation>0.16</wheelSeparation>
                <wheelDiameter>0.05</wheelDiameter>
                <broadcastTF>1</broadcastTF>
                <wheelTorque>20</wheelTorque>
                <wheelAcceleration>1.8</wheelAcceleration>
                <commandTopic>cmd_vel</commandTopic>
                <odometryFrame>odom</odometryFrame>
                <odometryTopic>odom</odometryTopic>
                <robotBaseFrame>base_footprint</robotBaseFrame>
            </plugin>
        </gazebo>
-->
  <!-- Transmission is important to link the joints and the controller -->
  <transmission name="right_bridge_joint_trans">
    <type>transmission_interface/SimpleTransmission</type>
    <joint name="right_bridge_to_bridge">
      <hardwareInterface>hardware_interface/EffortJointInterface</hardwareInterface>
    </joint>
    <actuator name="right_bridge_joint_motor">
      <hardwareInterface>hardware_interface/EffortJointInterface</hardwareInterface>
      <mechanicalReduction>1</mechanicalReduction>
      <motorTorqueConstant>100</motorTorqueConstant>
    </actuator>
  </transmission>
  <transmission name="left_bridge_joint_trans">
    <type>transmission_interface/SimpleTransmission</type>
    <joint name="left_bridge_to_bridge">
      <hardwareInterface>hardware_interface/EffortJointInterface</hardwareInterface>
    </joint>
    <actuator name="left_bridge_joint_motor">
      <hardwareInterface>hardware_interface/EffortJointInterface</hardwareInterface>
      <mechanicalReduction>1</mechanicalReduction>
      <motorTorqueConstant>100</motorTorqueConstant>
    </actuator>
  </transmission>
  <!--
	<transmission name="right_front_wheel_joint_trans">
		<type>transmission_interface/SimpleTransmission</type>
		<joint name="right_front_wheel_to_bridge" >
			<hardwareInterface>hardware_interface/VelocityJointInterface</hardwareInterface>
		</joint>
		<actuator name="right_front_wheel_joint_motor">
			<hardwareInterface>hardware_interface/VelocityJointInterface</hardwareInterface>
			<mechanicalReduction>1</mechanicalReduction>
		</actuator>
	</transmission>

	<transmission name="left_front_wheel_joint_trans">
		<type>transmission_interface/SimpleTransmission</type>
		<joint name="left_front_wheel_to_bridge" >
			<hardwareInterface>hardware_interface/VelocityJointInterface</hardwareInterface>
		</joint>
		<actuator name="left_front_wheel_joint_motor">
			<hardwareInterface>hardware_interface/VelocityJointInterface</hardwareInterface>
			<mechanicalReduction>1</mechanicalReduction>
		</actuator>
	</transmission>
-->
  <transmission name="right_back_wheel_joint_trans">
    <type>transmission_interface/SimpleTransmission</type>
    <joint name="right_back_wheel_joint">
      <hardwareInterface>hardware_interface/VelocityJointInterface</hardwareInterface>
    </joint>
    <actuator name="right_back_wheel_joint_motor">
      <hardwareInterface>hardware_interface/VelocityJointInterface</hardwareInterface>
      <mechanicalReduction>1</mechanicalReduction>
    </actuator>
  </transmission>
  <transmission name="left_back_wheel_joint_trans">
    <type>transmission_interface/SimpleTransmission</type>
    <joint name="left_back_wheel_joint">
      <hardwareInterface>hardware_interface/VelocityJointInterface</hardwareInterface>
    </joint>
    <actuator name="left_back_wheel_joint_motor">
      <hardwareInterface>hardware_interface/VelocityJointInterface</hardwareInterface>
      <mechanicalReduction>1</mechanicalReduction>
    </actuator>
  </transmission>
  <!-- <transmission name="right_front_wheel_joint_trans">
    <type>transmission_interface/SimpleTransmission</type>
    <joint name="right_front_wheel_to_bridge">
      <hardwareInterface>hardware_interface/VelocityJointInterface</hardwareInterface>
    </joint>
    <actuator name="right_front_wheel_joint_motor">
      <hardwareInterface>hardware_interface/VelocityJointInterface</hardwareInterface>
      <mechanicalReduction>1</mechanicalReduction>
    </actuator>
  </transmission>
  <transmission name="left_front_wheel_joint_trans">
    <type>transmission_interface/SimpleTransmission</type>
    <joint name="left_front_wheel_to_bridge">
      <hardwareInterface>hardware_interface/VelocityJointInterface</hardwareInterface>
    </joint>
    <actuator name="left_front_wheel_joint_motor">
      <hardwareInterface>hardware_interface/VelocityJointInterface</hardwareInterface>
      <mechanicalReduction>1</mechanicalReduction>
    </actuator>
  </transmission> -->
  <!-- Friction Parametres -->
  <!--
	<gazebo reference="left_bridge">
		<mu1>10000000000000</mu1>
		<mu2>10000000000000</mu2>
		<kp>100000000</kp>
		<kd>1</kd>
		<minDepth>0.01</minDepth>
		<maxVel>101</maxVel>
	</gazebo>

	<gazebo reference="right_bridge">
		<mu1>10000000000000</mu1>
		<mu2>10000000000000</mu2>
		<kp>100000000</kp>
		<kd>1</kd>
		<minDepth>0.01</minDepth>
		<maxVel>100</maxVel>
	</gazebo>
-->
  <gazebo reference="right_back_wheel">
    <mu1>10000000000000</mu1>
    <mu2>10000000000000</mu2>
    <kp>100000</kp>
    <kd>1</kd>
    <minDepth>0.01</minDepth>
    <maxVel>100</maxVel>
  </gazebo>
  <gazebo reference="left_back_wheel">
    <mu1>10000000000000</mu1>
    <mu2>10000000000000</mu2>
    <kp>100000</kp>
    <kd>1</kd>
    <minDepth>0.01</minDepth>
    <maxVel>100</maxVel>
  </gazebo>
  <gazebo reference="right_front_wheel">
    <mu1>10000000000000</mu1>
    <mu2>10000000000000</mu2>
    <kp>100000</kp>
    <kd>1</kd>
    <minDepth>0.01</minDepth>
    <maxVel>100</maxVel>
  </gazebo>
  <gazebo reference="left_front_wheel">
    <mu1>10000000000000</mu1>
    <mu2>10000000000000</mu2>
    <kp>100000</kp>
    <kd>1</kd>
    <minDepth>0.01</minDepth>
    <maxVel>100</maxVel>
  </gazebo>
  <gazebo>
    <plugin filename="libgazebo_ros_control.so" name="gazebo_ros_control">
      <robotNamespace/>
      <robotParam>robot_description</robotParam>
      <robotSimType>gazebo_ros_control/DefaultRobotHWSim</robotSimType>
      <legacyModeNS>true</legacyModeNS>
    </plugin>
  </gazebo>
</robot>

